[32m2025-02-10 09:44:28 -0300[0m - dagster - [34mDEBUG[0m - __ASSET_JOB - 19d2f6dd-16ad-4449-94ee-56635b3390fb - 86076 - LOGS_CAPTURED - Started capturing logs in process (pid: 86076).
[32m2025-02-10 09:44:32 -0300[0m - dagster - [34mDEBUG[0m - __ASSET_JOB - 19d2f6dd-16ad-4449-94ee-56635b3390fb - 86076 - airbyte_sync_8c1b4c52_e95a_4261_bda2_82af18aebaa2 - STEP_START - Started execution of step "airbyte_sync_8c1b4c52_e95a_4261_bda2_82af18aebaa2".
[32m2025-02-10 09:44:51 -0300[0m - dagster - [34mERROR[0m - [31m__ASSET_JOB - 19d2f6dd-16ad-4449-94ee-56635b3390fb - airbyte_sync_8c1b4c52_e95a_4261_bda2_82af18aebaa2 - Request to Airbyte API failed: HTTPConnectionPool(host='localhost', port=8000): Read timed out. (read timeout=15)[0m
[32m2025-02-10 09:45:12 -0300[0m - dagster - [34mERROR[0m - [31m__ASSET_JOB - 19d2f6dd-16ad-4449-94ee-56635b3390fb - airbyte_sync_8c1b4c52_e95a_4261_bda2_82af18aebaa2 - Request to Airbyte API failed: HTTPConnectionPool(host='localhost', port=8000): Read timed out. (read timeout=15)[0m
[32m2025-02-10 09:45:34 -0300[0m - dagster - [34mERROR[0m - [31m__ASSET_JOB - 19d2f6dd-16ad-4449-94ee-56635b3390fb - airbyte_sync_8c1b4c52_e95a_4261_bda2_82af18aebaa2 - Request to Airbyte API failed: HTTPConnectionPool(host='localhost', port=8000): Read timed out. (read timeout=15)[0m
[32m2025-02-10 09:45:59 -0300[0m - dagster - [34mERROR[0m - [31m__ASSET_JOB - 19d2f6dd-16ad-4449-94ee-56635b3390fb - airbyte_sync_8c1b4c52_e95a_4261_bda2_82af18aebaa2 - Request to Airbyte API failed: HTTPConnectionPool(host='localhost', port=8000): Read timed out. (read timeout=15)[0m
[32m2025-02-10 09:46:05 -0300[0m - dagster - [34mERROR[0m - [31m__ASSET_JOB - 19d2f6dd-16ad-4449-94ee-56635b3390fb - 86076 - airbyte_sync_8c1b4c52_e95a_4261_bda2_82af18aebaa2 - STEP_FAILURE - Execution of step "airbyte_sync_8c1b4c52_e95a_4261_bda2_82af18aebaa2" failed.

dagster._core.definitions.events.Failure: Max retries (3) exceeded with url: http://localhost:8000/api/v1/connections/get.

Stack Trace:
  File "/home/bajiks/.pyenv/versions/3.12.4/envs/mlops-tp-final/lib/python3.12/site-packages/dagster/_core/execution/plan/execute_plan.py", line 245, in dagster_event_sequence_for_step
    yield from check.generator(step_events)
  File "/home/bajiks/.pyenv/versions/3.12.4/envs/mlops-tp-final/lib/python3.12/site-packages/dagster/_core/execution/plan/execute_step.py", line 501, in core_dagster_event_sequence_for_step
    for user_event in _step_output_error_checked_user_event_sequence(
  File "/home/bajiks/.pyenv/versions/3.12.4/envs/mlops-tp-final/lib/python3.12/site-packages/dagster/_core/execution/plan/execute_step.py", line 184, in _step_output_error_checked_user_event_sequence
    for user_event in user_event_sequence:
  File "/home/bajiks/.pyenv/versions/3.12.4/envs/mlops-tp-final/lib/python3.12/site-packages/dagster/_core/execution/plan/execute_step.py", line 88, in _process_asset_results_to_events
    for user_event in user_event_sequence:
  File "/home/bajiks/.pyenv/versions/3.12.4/envs/mlops-tp-final/lib/python3.12/site-packages/dagster/_core/execution/plan/compute.py", line 190, in execute_core_compute
    for step_output in _yield_compute_results(step_context, inputs, compute_fn, compute_context):
  File "/home/bajiks/.pyenv/versions/3.12.4/envs/mlops-tp-final/lib/python3.12/site-packages/dagster/_core/execution/plan/compute.py", line 159, in _yield_compute_results
    for event in iterate_with_context(
  File "/home/bajiks/.pyenv/versions/3.12.4/envs/mlops-tp-final/lib/python3.12/site-packages/dagster/_utils/__init__.py", line 480, in iterate_with_context
    next_output = next(iterator)
                  ^^^^^^^^^^^^^^
  File "/home/bajiks/.pyenv/versions/3.12.4/envs/mlops-tp-final/lib/python3.12/site-packages/dagster_airbyte/asset_defs.py", line 223, in _assets
    ab_output = airbyte.sync_and_poll(connection_id=connection_id)
                ^^^^^^^^^^^^^^^^^^^^^^^^^^^^^^^^^^^^^^^^^^^^^^^^^^
  File "/home/bajiks/.pyenv/versions/3.12.4/envs/mlops-tp-final/lib/python3.12/site-packages/dagster_airbyte/resources.py", line 717, in sync_and_poll
    connection_details = self.get_connection_details(connection_id)
                         ^^^^^^^^^^^^^^^^^^^^^^^^^^^^^^^^^^^^^^^^^^
  File "/home/bajiks/.pyenv/versions/3.12.4/envs/mlops-tp-final/lib/python3.12/site-packages/dagster_airbyte/resources.py", line 695, in get_connection_details
    self.make_request(endpoint="/connections/get", data={"connectionId": connection_id})
  File "/home/bajiks/.pyenv/versions/3.12.4/envs/mlops-tp-final/lib/python3.12/site-packages/dagster_airbyte/resources.py", line 567, in make_request
    raise Failure(f"Max retries ({self.request_max_retries}) exceeded with url: {url}.")
[0m
