[32m2025-03-13 19:25:13 -0300[0m - dagster - [34mDEBUG[0m - dbt_and_training - 31874d6f-a8eb-42eb-a284-975318ed98fe - 689128 - LOGS_CAPTURED - Started capturing logs in process (pid: 689128).
[32m2025-03-13 19:25:13 -0300[0m - dagster - [34mDEBUG[0m - dbt_and_training - 31874d6f-a8eb-42eb-a284-975318ed98fe - 689128 - model_stored - STEP_START - Started execution of step "model_stored".
[32m2025-03-13 19:25:13 -0300[0m - dagster - [34mDEBUG[0m - dbt_and_training - 31874d6f-a8eb-42eb-a284-975318ed98fe - 689128 - model_stored - LOADED_INPUT - Loaded input "model_trained" using input manager "io_manager", from output "result" of step "model_trained"
[32m2025-03-13 19:25:13 -0300[0m - dagster - [34mDEBUG[0m - dbt_and_training - 31874d6f-a8eb-42eb-a284-975318ed98fe - 689128 - model_stored - STEP_INPUT - Got input "model_trained" of type "Any". (Type check passed).
[32m2025-03-13 19:25:13 -0300[0m - dagster - [34mINFO[0m - dbt_and_training - 31874d6f-a8eb-42eb-a284-975318ed98fe - model_stored - Tipo de model_trained: <class 'pandas.core.frame.DataFrame'>
2025/03/13 19:25:13 WARNING mlflow.tensorflow: You are saving a TensorFlow Core model or Keras model without a signature. Inference with mlflow.pyfunc.spark_udf() will not work unless the model's pyfunc representation accepts pandas DataFrames as inference inputs.
[32m2025-03-13 19:25:13 -0300[0m - dagster - [34mERROR[0m - [31mdbt_and_training - 31874d6f-a8eb-42eb-a284-975318ed98fe - 689128 - model_stored - STEP_FAILURE - Execution of step "model_stored" failed.

dagster._core.errors.DagsterExecutionStepExecutionError: Error occurred while executing op "model_stored"::

mlflow.exceptions.MlflowException: Unknown model type: <class 'pandas.core.frame.DataFrame'>

Stack Trace:
  File "/home/bajiks/.pyenv/versions/3.12.4/envs/mlops-tp-final/lib/python3.12/site-packages/dagster/_core/execution/plan/utils.py", line 56, in op_execution_error_boundary
    yield
  File "/home/bajiks/.pyenv/versions/3.12.4/envs/mlops-tp-final/lib/python3.12/site-packages/dagster/_utils/__init__.py", line 480, in iterate_with_context
    next_output = next(iterator)
                  ^^^^^^^^^^^^^^
  File "/home/bajiks/.pyenv/versions/3.12.4/envs/mlops-tp-final/lib/python3.12/site-packages/dagster/_core/execution/plan/compute_generator.py", line 127, in _coerce_op_compute_fn_to_iterator
    result = invoke_compute_fn(
             ^^^^^^^^^^^^^^^^^^
  File "/home/bajiks/.pyenv/versions/3.12.4/envs/mlops-tp-final/lib/python3.12/site-packages/dagster/_core/execution/plan/compute_generator.py", line 115, in invoke_compute_fn
    return fn(context, **args_to_pass) if context_arg_provided else fn(**args_to_pass)
           ^^^^^^^^^^^^^^^^^^^^^^^^^^^
  File "/home/bajiks/code/Bajiks/ITBA/final-project/recommender_system/recommender_system/assets/recommender/train_model.py", line 117, in log_model
    logged_model = mlflow.tensorflow.log_model(
                   ^^^^^^^^^^^^^^^^^^^^^^^^^^^^
  File "/home/bajiks/.pyenv/versions/3.12.4/envs/mlops-tp-final/lib/python3.12/site-packages/mlflow/tensorflow/__init__.py", line 217, in log_model
    return Model.log(
           ^^^^^^^^^^
  File "/home/bajiks/.pyenv/versions/3.12.4/envs/mlops-tp-final/lib/python3.12/site-packages/mlflow/models/model.py", line 796, in log
    flavor.save_model(path=local_path, mlflow_model=mlflow_model, **kwargs)
  File "/home/bajiks/.pyenv/versions/3.12.4/envs/mlops-tp-final/lib/python3.12/site-packages/mlflow/tensorflow/__init__.py", line 459, in save_model
    raise MlflowException(f"Unknown model type: {type(model)}")
[0m
