[32m2025-03-13 20:51:54 -0300[0m - dagster - [34mDEBUG[0m - dbt_and_training - 57444b1e-d418-4c03-b4fe-5c3cef946248 - 933264 - LOGS_CAPTURED - Started capturing logs in process (pid: 933264).
[32m2025-03-13 20:51:54 -0300[0m - dagster - [34mDEBUG[0m - dbt_and_training - 57444b1e-d418-4c03-b4fe-5c3cef946248 - 933264 - model_metrics - STEP_START - Started execution of step "model_metrics".
[32m2025-03-13 20:51:54 -0300[0m - dagster - [34mDEBUG[0m - dbt_and_training - 57444b1e-d418-4c03-b4fe-5c3cef946248 - 933264 - model_metrics - LOADED_INPUT - Loaded input "X_test" using input manager "io_manager", from output "X_test" of step "split_data"
[32m2025-03-13 20:51:54 -0300[0m - dagster - [34mDEBUG[0m - dbt_and_training - 57444b1e-d418-4c03-b4fe-5c3cef946248 - 933264 - model_metrics - LOADED_INPUT - Loaded input "model_stored" using input manager "io_manager", from output "model_stored" of step "log_model"
[32m2025-03-13 20:51:55 -0300[0m - dagster - [34mDEBUG[0m - dbt_and_training - 57444b1e-d418-4c03-b4fe-5c3cef946248 - 933264 - model_metrics - LOADED_INPUT - Loaded input "y_test" using input manager "io_manager", from output "y_test" of step "split_data"
[32m2025-03-13 20:51:55 -0300[0m - dagster - [34mDEBUG[0m - dbt_and_training - 57444b1e-d418-4c03-b4fe-5c3cef946248 - 933264 - model_metrics - STEP_INPUT - Got input "X_test" of type "Any". (Type check passed).
[32m2025-03-13 20:51:55 -0300[0m - dagster - [34mDEBUG[0m - dbt_and_training - 57444b1e-d418-4c03-b4fe-5c3cef946248 - 933264 - model_metrics - STEP_INPUT - Got input "model_stored" of type "Any". (Type check passed).
[32m2025-03-13 20:51:55 -0300[0m - dagster - [34mDEBUG[0m - dbt_and_training - 57444b1e-d418-4c03-b4fe-5c3cef946248 - 933264 - model_metrics - STEP_INPUT - Got input "y_test" of type "Any". (Type check passed).
[32m2025-03-13 20:51:55 -0300[0m - dagster - [34mERROR[0m - [31mdbt_and_training - 57444b1e-d418-4c03-b4fe-5c3cef946248 - 933264 - model_metrics - STEP_FAILURE - Execution of step "model_metrics" failed.

dagster._core.errors.DagsterExecutionStepExecutionError: Error occurred while executing op "model_metrics"::

KeyError: 'model_uri'

Stack Trace:
  File "/home/bajiks/.pyenv/versions/3.12.4/envs/mlops-tp-final/lib/python3.12/site-packages/dagster/_core/execution/plan/utils.py", line 56, in op_execution_error_boundary
    yield
  File "/home/bajiks/.pyenv/versions/3.12.4/envs/mlops-tp-final/lib/python3.12/site-packages/dagster/_utils/__init__.py", line 480, in iterate_with_context
    next_output = next(iterator)
                  ^^^^^^^^^^^^^^
  File "/home/bajiks/.pyenv/versions/3.12.4/envs/mlops-tp-final/lib/python3.12/site-packages/dagster/_core/execution/plan/compute_generator.py", line 127, in _coerce_op_compute_fn_to_iterator
    result = invoke_compute_fn(
             ^^^^^^^^^^^^^^^^^^
  File "/home/bajiks/.pyenv/versions/3.12.4/envs/mlops-tp-final/lib/python3.12/site-packages/dagster/_core/execution/plan/compute_generator.py", line 115, in invoke_compute_fn
    return fn(context, **args_to_pass) if context_arg_provided else fn(**args_to_pass)
           ^^^^^^^^^^^^^^^^^^^^^^^^^^^
  File "/home/bajiks/code/Bajiks/ITBA/final-project/recommender_system/recommender_system/assets/recommender/train_model.py", line 140, in model_metrics
    logged_model = model_stored['model_uri']
                   ~~~~~~~~~~~~^^^^^^^^^^^^^
  File "/home/bajiks/.pyenv/versions/3.12.4/envs/mlops-tp-final/lib/python3.12/site-packages/pandas/core/frame.py", line 4102, in __getitem__
    indexer = self.columns.get_loc(key)
              ^^^^^^^^^^^^^^^^^^^^^^^^^
  File "/home/bajiks/.pyenv/versions/3.12.4/envs/mlops-tp-final/lib/python3.12/site-packages/pandas/core/indexes/base.py", line 3812, in get_loc
    raise KeyError(key) from err

The above exception was caused by the following exception:
KeyError: 'model_uri'

Stack Trace:
  File "/home/bajiks/.pyenv/versions/3.12.4/envs/mlops-tp-final/lib/python3.12/site-packages/pandas/core/indexes/base.py", line 3805, in get_loc
    return self._engine.get_loc(casted_key)
           ^^^^^^^^^^^^^^^^^^^^^^^^^^^^^^^^
  File "index.pyx", line 167, in pandas._libs.index.IndexEngine.get_loc
  File "index.pyx", line 196, in pandas._libs.index.IndexEngine.get_loc
  File "pandas/_libs/hashtable_class_helper.pxi", line 7081, in pandas._libs.hashtable.PyObjectHashTable.get_item
  File "pandas/_libs/hashtable_class_helper.pxi", line 7089, in pandas._libs.hashtable.PyObjectHashTable.get_item
[0m
