[32m2025-03-13 17:27:18 -0300[0m - dagster - [34mDEBUG[0m - __ASSET_JOB - f377de4d-5006-41f8-83d7-e4fd83fea284 - 213559 - LOGS_CAPTURED - Started capturing logs in process (pid: 213559).
[32m2025-03-13 17:27:18 -0300[0m - dagster - [34mDEBUG[0m - __ASSET_JOB - f377de4d-5006-41f8-83d7-e4fd83fea284 - 213559 - split_data - STEP_START - Started execution of step "split_data".
[32m2025-03-13 17:27:19 -0300[0m - dagster - [34mDEBUG[0m - __ASSET_JOB - f377de4d-5006-41f8-83d7-e4fd83fea284 - 213559 - split_data - LOADED_INPUT - Loaded input "preprocessed_training_data" using input manager "io_manager"
[32m2025-03-13 17:27:19 -0300[0m - dagster - [34mDEBUG[0m - __ASSET_JOB - f377de4d-5006-41f8-83d7-e4fd83fea284 - 213559 - split_data - STEP_INPUT - Got input "preprocessed_training_data" of type "Any". (Type check passed).
[32m2025-03-13 17:27:19 -0300[0m - dagster - [34mERROR[0m - [31m__ASSET_JOB - f377de4d-5006-41f8-83d7-e4fd83fea284 - 213559 - split_data - STEP_FAILURE - Execution of step "split_data" failed.

dagster._core.errors.DagsterExecutionStepExecutionError: Error occurred while executing op "split_data"::

KeyError: "None of [Index(['encoded_user_id', 'encoded_movie_id'], dtype='object')] are in the [columns]"

Stack Trace:
  File "/home/bajiks/.pyenv/versions/3.12.4/envs/mlops-tp-final/lib/python3.12/site-packages/dagster/_core/execution/plan/utils.py", line 56, in op_execution_error_boundary
    yield
  File "/home/bajiks/.pyenv/versions/3.12.4/envs/mlops-tp-final/lib/python3.12/site-packages/dagster/_utils/__init__.py", line 480, in iterate_with_context
    next_output = next(iterator)
                  ^^^^^^^^^^^^^^
  File "/home/bajiks/.pyenv/versions/3.12.4/envs/mlops-tp-final/lib/python3.12/site-packages/dagster/_core/execution/plan/compute_generator.py", line 127, in _coerce_op_compute_fn_to_iterator
    result = invoke_compute_fn(
             ^^^^^^^^^^^^^^^^^^
  File "/home/bajiks/.pyenv/versions/3.12.4/envs/mlops-tp-final/lib/python3.12/site-packages/dagster/_core/execution/plan/compute_generator.py", line 115, in invoke_compute_fn
    return fn(context, **args_to_pass) if context_arg_provided else fn(**args_to_pass)
           ^^^^^^^^^^^^^^^^^^^^^^^^^^^
  File "/home/bajiks/code/Bajiks/ITBA/final-project/recommender_system/recommender_system/assets/recommender/train_model.py", line 45, in split_data
    preprocessed_training_data[['encoded_user_id', 'encoded_movie_id']],
    ~~~~~~~~~~~~~~~~~~~~~~~~~~^^^^^^^^^^^^^^^^^^^^^^^^^^^^^^^^^^^^^^^^^
  File "/home/bajiks/.pyenv/versions/3.12.4/envs/mlops-tp-final/lib/python3.12/site-packages/pandas/core/frame.py", line 4108, in __getitem__
    indexer = self.columns._get_indexer_strict(key, "columns")[1]
              ^^^^^^^^^^^^^^^^^^^^^^^^^^^^^^^^^^^^^^^^^^^^^^^^
  File "/home/bajiks/.pyenv/versions/3.12.4/envs/mlops-tp-final/lib/python3.12/site-packages/pandas/core/indexes/base.py", line 6200, in _get_indexer_strict
    self._raise_if_missing(keyarr, indexer, axis_name)
  File "/home/bajiks/.pyenv/versions/3.12.4/envs/mlops-tp-final/lib/python3.12/site-packages/pandas/core/indexes/base.py", line 6249, in _raise_if_missing
    raise KeyError(f"None of [{key}] are in the [{axis_name}]")
[0m
